output/next_pitch_model_sweep_metrics.json
[
  {
    "model": "lookup_global",
    "dataset": "2025_holdout",
    "rows": 52324,
    "accuracy": 0.3192034248146166,
    "top2_accuracy": 0.4773144255026374,
    "top3_accuracy": 0.5963037994037154,
    "macro_f1": 0.037225660787796794,
    "avg_actual_probability": 0.17306086167455587,
    "avg_confidence": 0.3192034248146166
  },
  {
    "model": "lookup_global_arsenal_masked",
    "dataset": "2025_holdout",
    "rows": 52324,
    "accuracy": 0.3357541472364498,
    "top2_accuracy": 0.5102056417705069,
    "top3_accuracy": 0.6769360140662029,
    "macro_f1": 0.05129512166643196,
    "avg_actual_probability": 0.2391724227290576,
    "avg_confidence": 0.42791037255817443
  },
  {
    "model": "lookup_global",
    "dataset": "2026_to_date",
    "rows": 82282,
    "accuracy": 0.2982669356602902,
    "top2_accuracy": 0.45956588318222696,
    "top3_accuracy": 0.5787414015215965,
    "macro_f1": 0.035344981536848535,
    "avg_actual_probability": 0.1676251996804715,
    "avg_confidence": 0.3192034248146166
  },
  {
    "model": "lookup_global_arsenal_masked",
    "dataset": "2026_to_date",
    "rows": 82282,
    "accuracy": 0.3139204200189592,
    "top2_accuracy": 0.49462822974648163,
    "top3_accuracy": 0.6542014049245278,
    "macro_f1": 0.04862221068751208,
    "avg_actual_probability": 0.22884427590173353,
    "avg_confidence": 0.4299380157930824
  },
  {
    "model": "lookup_pitcher",
    "dataset": "2025_holdout",
    "rows": 52324,
    "accuracy": 0.379787478021558,
    "top2_accuracy": 0.6271691766684504,
    "top3_accuracy": 0.79529470223989,
    "macro_f1": 0.1297019751435996,
    "avg_actual_probability": 0.26867711113191695,
    "avg_confidence": 0.3811850148596826
  },
  {
    "model": "lookup_pitcher_arsenal_masked",
    "dataset": "2025_holdout",
    "rows": 52324,
    "accuracy": 0.379787478021558,
    "top2_accuracy": 0.6271691766684504,
    "top3_accuracy": 0.79529470223989,
    "macro_f1": 0.1297019751435996,
    "avg_actual_probability": 0.2703019472191452,
    "avg_confidence": 0.383478334534097
  },
  {
    "model": "lookup_pitcher",
    "dataset": "2026_to_date",
    "rows": 82282,
    "accuracy": 0.3388347390680829,
    "top2_accuracy": 0.5731630247198658,
    "top3_accuracy": 0.7524488952626334,
    "macro_f1": 0.10673138876112928,
    "avg_actual_probability": 0.2497976892973722,
    "avg_confidence": 0.37889415338489973
  },
  {
    "model": "lookup_pitcher_arsenal_masked",
    "dataset": "2026_to_date",
    "rows": 82282,
    "accuracy": 0.3388347390680829,
    "top2_accuracy": 0.5731630247198658,
    "top3_accuracy": 0.7524488952626334,
    "macro_f1": 0.10673138876112928,
    "avg_actual_probability": 0.25122796069480613,
    "avg_confidence": 0.3812443735602455
  },
  {
    "model": "lookup_pitcher_count",
    "dataset": "2025_holdout",
    "rows": 52324,
    "accuracy": 0.4045371148994725,
    "top2_accuracy": 0.6512499044415565,
    "top3_accuracy": 0.815247305251892,
    "macro_f1": 0.22599907807767153,
    "avg_actual_probability": 0.27683872004284227,
    "avg_confidence": 0.389004477487551
  },
  {
    "model": "lookup_pitcher_count_arsenal_masked",
    "dataset": "2025_holdout",
    "rows": 52324,
    "accuracy": 0.4045371148994725,
    "top2_accuracy": 0.6512499044415565,
    "top3_accuracy": 0.8152855286293097,
    "macro_f1": 0.22599907807767153,
    "avg_actual_probability": 0.2899954568876608,
    "avg_confidence": 0.4069639619850346
  },
  {
    "model": "lookup_pitcher_count",
    "dataset": "2026_to_date",
    "rows": 82282,
    "accuracy": 0.36169514596144964,
    "top2_accuracy": 0.5986120901290684,
    "top3_accuracy": 0.7683819061277072,
    "macro_f1": 0.18913686477467093,
    "avg_actual_probability": 0.25632790313827547,
    "avg_confidence": 0.3875352438432497
  },
  {
    "model": "lookup_pitcher_count_arsenal_masked",
    "dataset": "2026_to_date",
    "rows": 82282,
    "accuracy": 0.36169514596144964,
    "top2_accuracy": 0.59866070343453,
    "top3_accuracy": 0.7686006660022848,
    "macro_f1": 0.18913686477467093,
    "avg_actual_probability": 0.2684284965909037,
    "avg_confidence": 0.40569500464936087
  },
  {
    "model": "lookup_pitcher_prev",
    "dataset": "2025_holdout",
    "rows": 52324,
    "accuracy": 0.39872716153199295,
    "top2_accuracy": 0.6510205641770507,
    "top3_accuracy": 0.8148841831664246,
    "macro_f1": 0.19186055529726234,
    "avg_actual_probability": 0.2774448167393007,
    "avg_confidence": 0.3926283423687919
  },
  {
    "model": "lookup_pitcher_prev_arsenal_masked",
    "dataset": "2025_holdout",
    "rows": 52324,
    "accuracy": 0.39872716153199295,
    "top2_accuracy": 0.6510396758657595,
    "top3_accuracy": 0.8148650714777158,
    "macro_f1": 0.19186474782637178,
    "avg_actual_probability": 0.2840415290615237,
    "avg_confidence": 0.4020310898602017
  },
  {
    "model": "lookup_pitcher_prev",
    "dataset": "2026_to_date",
    "rows": 82282,
    "accuracy": 0.3511095986971634,
    "top2_accuracy": 0.5929729466955106,
    "top3_accuracy": 0.7647480615444447,
    "macro_f1": 0.1576776196718634,
    "avg_actual_probability": 0.2548269923751007,
    "avg_confidence": 0.38726226296091115
  },
  {
    "model": "lookup_pitcher_prev_arsenal_masked",
    "dataset": "2026_to_date",
    "rows": 82282,
    "accuracy": 0.3507814588852969,
    "top2_accuracy": 0.5930944799591649,
    "top3_accuracy": 0.764954668092657,
    "macro_f1": 0.15752276992442077,
    "avg_actual_probability": 0.2614376537391801,
    "avg_confidence": 0.39813865205778376
  },
  {
    "model": "lookup_pitcher_count_prev",
    "dataset": "2025_holdout",
    "rows": 52324,
    "accuracy": 0.4101368396911551,
    "top2_accuracy": 0.6579198838009327,
    "top3_accuracy": 0.8150753000535127,
    "macro_f1": 0.2465857313768862,
    "avg_actual_probability": 0.25729776844946095,
    "avg_confidence": 0.3640737148943036
  },
  {
    "model": "lookup_pitcher_count_prev_arsenal_masked",
    "dataset": "2025_holdout",
    "rows": 52324,
    "accuracy": 0.4100986163137375,
    "top2_accuracy": 0.6581683357541472,
    "top3_accuracy": 0.8175789312743674,
    "macro_f1": 0.24654709370533018,
    "avg_actual_probability": 0.2931896861527155,
    "avg_confidence": 0.4144089114224974
  },
  {
    "model": "lookup_pitcher_count_prev",
    "dataset": "2026_to_date",
    "rows": 82282,
    "accuracy": 0.36571789698840573,
    "top2_accuracy": 0.5981502637271822,
    "top3_accuracy": 0.7611992902457403,
    "macro_f1": 0.20931909379025349,
    "avg_actual_probability": 0.2358930048446222,
    "avg_confidence": 0.36042026301713714
  },
  {
    "model": "lookup_pitcher_count_prev_arsenal_masked",
    "dataset": "2026_to_date",
    "rows": 82282,
    "accuracy": 0.36579081694659826,
    "top2_accuracy": 0.598745776719088,
    "top3_accuracy": 0.7644563817116745,
    "macro_f1": 0.20933047929413834,
    "avg_actual_probability": 0.2693752215482272,
    "avg_confidence": 0.4119196953228072
  },
  {
    "model": "lookup_pitcher_count_prev_stand",
    "dataset": "2025_holdout",
    "rows": 52324,
    "accuracy": 0.42177585811482304,
    "top2_accuracy": 0.6789236296919196,
    "top3_accuracy": 0.8322949315801544,
    "macro_f1": 0.2582175935792083,
    "avg_actual_probability": 0.2526784971397417,
    "avg_confidence": 0.3501732104517104
  },
  {
    "model": "lookup_pitcher_count_prev_stand_arsenal_masked",
    "dataset": "2025_holdout",
    "rows": 52324,
    "accuracy": 0.4217567464261142,
    "top2_accuracy": 0.6805481232321688,
    "top3_accuracy": 0.8404173992814005,
    "macro_f1": 0.2581921417419637,
    "avg_actual_probability": 0.3040056502879274,
    "avg_confidence": 0.42157340625538
  },
  {
    "model": "lookup_pitcher_count_prev_stand",
    "dataset": "2026_to_date",
    "rows": 82282,
    "accuracy": 0.3730220461340269,
    "top2_accuracy": 0.6163802532753214,
    "top3_accuracy": 0.7696580053960769,
    "macro_f1": 0.22640202873869486,
    "avg_actual_probability": 0.23147195549867788,
    "avg_confidence": 0.34658072290485614
